Workbook

Sheet Cover Page
B2: NVIDIA DCF Valuation Using Financial Statements
B4: Date | C4: November 12, 2025
B5: Prepared By | C5: Braeden Tuazon
B6: Purpose | C6: This model estimates the intrinsic value of NVIDIA using a Discounted Cash Flow (DCF) approach, based on real financial statement data (income statement, balance sheet, and cash flows) and market inputs such as WACC, beta, and risk-free rate.
B7: Data Sources | C7: NVIDIA 10-Q and 10-K reports, Yahoo Finance, AlphaSpread, Bloomberg, Morningstar, GuruFocus, Finbox, FactSet, Reuters, U.S. Treasury, and self-calculated estimates where applicable.
B9: Key Valuation Results | C9: Values
B10: Market Share Price | C10: ='DCF Valuation'!J5 -> 193.16
B11: DCF Implied Share Price | C11: ='DCF Valuation'!J4 -> 739.15195
B12: Upside Potential | C12: ='DCF Valuation'!J6 -> 2.8266305
B13: WACC | C13: =WACC!F21 -> 0.10255877
B14: Terminal Growth Rate | C14: 3.5%
B15: Valuation Date | C15: November 12, 2025
B17: Key Assumptions Table | C17: Values
B18: Cost of Equity | C18: =WACC!F11 -> 0.1027
B19: Beta | C19: 1.2
B20: Risk-Free Rate | C20: =WACC!F12 -> 0.0415
B21: Market Risk Premium | C21: =WACC!F14 -> 0.051
B22: Cost of Debt | C22: =WACC!F18 -> 0.039
B23: Tax Rate | C23: =WACC!F19 -> 0.17
B25: Workbook Tabs Overview | C25: Description
B26: Revenue Streams | C26: Breakdown of NVIDIA's product/service revenue over time
B27: Income Statement | C27: Quarterly income performance including revenue, expenses, and net income
B28: Balance Sheet | C28: Snapshot of assets, liabilities, and equity over time
B29: Cash Flow Statement | C29: Cash inflows/outflows from operations, investing and financing activities
B30: Working Capital | C30: Detailed calculation of current assets and liabilities for forecasting purposes
B31: Debt | C31: NVIDIA's debt levels, interest expense, and cost of debt inputs
B32: Fixed Assets | C32: Capital expenditures, depreciation, and asset base tracking
B33: WACC | C33: Weighted Average Cost of Capital calculation based on market inputs
B34: DCF Valuation | C34: Free Cash Flow forecast, terminal value, and intrinsic value estimation
B36: Disclaimer: For academic use only. Not intended as financial or investment advice.

Sheet Revenue Streams
A2: Revenue Streams
A4: ($ in millions) | B4: Q1 2020 | C4: Q2 2020 | D4: Q3 2020 | E4: Q4 2020 | F4: Q1 2021 | G4: Q2 2021 | H4: Q3 2021 | I4: Q4 2021 | J4: Q1 2022 | K4: Q2 2022 | L4: Q3 2022 | M4: Q4 2022 | N4: Q1 2023 | O4: Q2 2023 | P4: Q3 2023 | Q4: Q4 2023 | R4: Q1 2024 | S4: Q2 2024 | T4: Q3 2024 | U4: Q4 2024
A5: Data Center | B5: =1/3*B25+2/3*C25 -> 1083.3333 | C5: =1/3*C25+2/3*D25 -> 1548.3333 | D5: =1/3*D25+2/3*E25 -> 1850.6667 | E5: =1/3*E25+2/3*F25 -> 1902 | F5: =1/3*F25+2/3*G25 -> 1999.6667 | G5: =1/3*G25+2/3*H25 -> 2260 | H5: =1/3*H25+2/3*I25 -> 2746 | I5: =1/3*I25+2/3*J25 -> 3154 | ... T5: =1/3*T25+2/3*U25 -> 29303.667 | U5: =1/3*U25+2/3*W22 -> 10266.667
A6: Data Center | B6: =B5/B$20 -> 0.35078251 | C6: =C5/C$20 -> 0.42961524 | D6: =D5/D$20 -> 0.41687941 | E6: =E5/E$20 -> 0.38732012 | F6: =F5/F$20 -> 0.3674732 | G6: =G5/G$20 -> 0.36305221 | H6: =H5/H$20 -> 0.39772124 | I6: =I5/I$20 -> 0.42261825 | ... U6: =U5/U$20 -> 0.8779431
A8: Gaming | B8: =1/3*B29+2/3*C29 -> 1389.6667 | C8: =1/3*C29+2/3*D29 -> 1549 | D8: =1/3*D29+2/3*E29 -> 2065.3333 | E8: =1/3*E29+2/3*F29 -> 2420.3333 | F8: =1/3*F29+2/3*G29 -> 2671.6667 | G8: =1/3*G29+2/3*H29 -> 2960.6667 | H8: =1/3*H29+2/3*I29 -> 3167.6667 | I8: =1/3*I29+2/3*J29 -> 3353.6667 | ... T8: =1/3*T29+2/3*U29 -> 3165 | U8: =1/3*U29+2/3*W26 -> 1100
A9: Gaming | B9: =B8/B$20 -> 0.44997302 | C9: =C8/C$20 -> 0.42980022 | D9: =D8/D$20 -> 0.46523502 | E9: =E8/E$20 -> 0.49287266 | F9: =F8/F$20 -> 0.49096478 | G9: =G8/G$20 -> 0.4756091 | H9: =H8/H$20 -> 0.45879399 | I9: =I8/I$20 -> 0.44937246 | ... U9: =U8/U$20 -> 0.094065333
A11: Professional Visualization | B11: =1/3*B33+2/3*C33 -> 315 | C11: =1/3*C33+2/3*D33 -> 237.66667 | D11: =1/3*D33+2/3*E33 -> 225 | E11: =1/3*E33+2/3*F33 -> 283.33333 | F11: =1/3*F33+2/3*G33 -> 350.33333 | G11: =1/3*G33+2/3*H33 -> 470 | H11: =1/3*H33+2/3*I33 -> 557.66667 | I11: =1/3*I33+2/3*J33 -> 621 | ... T11: =1/3*T33+2/3*U33 -> 475.33333 | U11: =1/3*U33+2/3*W30 -> 162
A12: Professional Visualization | B12: =B11/B$20 -> 0.10199676 | C12: =C11/C$20 -> 0.065945246 | D12: =D11/D$20 -> 0.050683286 | E12: =E11/E$20 -> 0.057697529 | F12: =F11/F$20 -> 0.064379786 | G12: =G11/G$20 -> 0.075502008 | H12: =H11/H$20 -> 0.080770531 | I12: =I11/I$20 -> 0.083210505 | ... U12: =U11/U$20 -> 0.013853258
A14: Auto | B14: =1/3*B37+2/3*C37 -> 157.66667 | C14: =1/3*C37+2/3*D37 -> 125.66667 | D14: =1/3*D37+2/3*E37 -> 120.33333 | E14: =1/3*E37+2/3*F37 -> 138.33333 | F14: =1/3*F37+2/3*G37 -> 151 | G14: =1/3*G37+2/3*H37 -> 152.66667 | H14: =1/3*H37+2/3*I37 -> 140.66667 | I14: =1/3*I37+2/3*J37 -> 128.33333 | ... T14: =1/3*T37+2/3*U37 -> 414.66667 | U14: =1/3*U37+2/3*W34 -> 149.66667
A15: Auto | B15: =B14/B$20 -> 0.051052348 | C15: =C14/C$20 -> 0.034868664 | D15: =D14/D$20 -> 0.027106172 | E15: =E14/E$20 -> 0.02816997 | F15: =F14/F$20 -> 0.027748851 | G15: =G14/G$20 -> 0.024524766 | H15: =H14/H$20 -> 0.020373678 | I15: =I14/I$20 -> 0.017195944 | ... U15: =U14/U$20 -> 0.012798586
A17: OEM & Other | B17: =1/3*B41+2/3*C41 -> 142.66667 | C17: =1/3*C41+2/3*D41 -> 143.33333 | D17: =1/3*D41+2/3*E41 -> 178 | E17: =1/3*E41+2/3*F41 -> 166.66667 | F17: =1/3*F41+2/3*G41 -> 269 | G17: =1/3*G41+2/3*H41 -> 381.66667 | H17: =1/3*H41+2/3*I41 -> 292.33333 | I17: =1/3*I41+2/3*J41 -> 206 | ... T17: =1/3*T41+2/3*U41 -> 42.666667 | U17: =1/3*U41+2/3*W38 -> 15.666667
A18: OEM & Other | B18: =B17/B$20 -> 0.046195359 | C18: =C17/C$20 -> 0.039770625 | D18: =D17/D$20 -> 0.040096111 | E18: =E17/E$20 -> 0.033939723 | F18: =F17/F$20 -> 0.049433384 | G18: =G17/G$20 -> 0.061311914 | H18: =H17/H$20 -> 0.042340559 | I18: =I17/I$20 -> 0.027602841 | ... U18: =U17/U$20 -> 0.0013397184
A20: Total | B20: =SUM(B5,B8,B11,B14,B17) -> 3088.3333 | C20: =SUM(C5,C8,C11,C14,C17) -> 3604 | D20: =SUM(D5,D8,D11,D14,D17) -> 4439.3333 | E20: =SUM(E5,E8,E11,E14,E17) -> 4910.6667 | F20: =SUM(F5,F8,F11,F14,F17) -> 5441.6667 | G20: =SUM(G5,G8,G11,G14,G17) -> 6225 | H20: =SUM(H5,H8,H11,H14,H17) -> 6904.3333 | I20: =SUM(I5,I8,I11,I14,I17) -> 7463 | ... U20: =SUM(U5,U8,U11,U14,U17) -> 11694
A22: Revenue Streams
A24: ($ in millions) | B24: Q4 2020 | C24: Q1 2021 | D24: Q2 2021 | E24: Q3 2021 | F24: Q4 2021 | G24: Q1 2022 | H24: Q2 2022 | I24: Q3 2022 | J24: Q4 2022 | K24: Q1 2023 | L24: Q2 2023 | M24: Q3 2023 | N24: Q4 2023 | O24: Q1 2024 | P24: Q2 2024 | Q24: Q3 2024 | R24: Q4 2024 | S24: Q1 2025 | T24: Q2 2025 | U24: Q3 2025
A25: Data Center | B25: 968 | C25: 1141 | D25: 1752 | E25: 1900 | F25: 1903 | G25: 2048 | H25: 2366 | I25: 2936 | J25: 3263 | K25: 3750 | L25: 3806 | M25: 3833 | N25: 3616 | O25: 4284 | P25: 10323 | Q25: 14514 | R25: 18404 | S25: 22563 | T25: 26311 | U25: 30800
A26: % change | C26: =C25/B25-1 -> 0.17871901 | D26: =D25/C25-1 -> 0.53549518 | E26: =E25/D25-1 -> 0.084474886 | F26: =F25/E25-1 -> 0.0015789474 | G26: =G25/F25-1 -> 0.076195481 | H26: =H25/G25-1 -> 0.15527344 | I26: =I25/H25-1 -> 0.24091293 | J26: =J25/I25-1 -> 0.11137602 | ... U26: =U25/T25-1 -> 0.17061305
A27: % of total | B27: =B25/B$45 -> 0.31175523 | C27: =C25/C$45 -> 0.37045455 | D27: =D25/D$45 -> 0.45318158 | E27: =E25/E$45 -> 0.40203132 | F27: =F25/F$45 -> 0.38037178 | G27: =G25/G$45 -> 0.36177354 | H27: =H25/H$45 -> 0.36360842 | I27: =I25/I$45 -> 0.41334647 | ... U27: =U25/U$45 -> 0.8779431
A29: Gaming | B29: 1491 | C29: 1339 | D29: 1654 | E29: 2271 | F29: 2495 | G29: 2760 | H29: 3061 | I29: 3221 | J29: 3420 | K29: 3620 | L29: 2042 | M29: 1574 | N29: 1831 | O29: 2240 | P29: 2486 | Q29: 2856 | R29: 2865 | S29: 2649 | T29: 2895 | U29: 3300
A30: % change | C30: =C29/B29-1 -> -0.101945 | D30: =D29/C29-1 -> 0.23525019 | E30: =E29/D29-1 -> 0.37303507 | F30: =F29/E29-1 -> 0.098634963 | G30: =G29/F29-1 -> 0.10621242 | H30: =H29/G29-1 -> 0.10905797 | I30: =I29/H29-1 -> 0.0522705 | J30: =J29/I29-1 -> 0.061782055 | ... U30: =U29/T29-1 -> 0.13989637
A31: % of total | B31: =B29/B$45 -> 0.48019324 | C31: =C29/C$45 -> 0.43474026 | D31: =D29/D$45 -> 0.42783238 | E31: =E29/E$45 -> 0.48053322 | F31: =F29/F$45 -> 0.49870078 | G31: =G29/G$45 -> 0.48754637 | H31: =H29/H$45 -> 0.47041647 | I31: =I29/I$45 -> 0.45347036 | ... U31: =U29/U$45 -> 0.094065333
A33: Professional Visualization | B33: 331 | C33: 307 | D33: 203 | E33: 236 | F33: 307 | G33: 372 | H33: 519 | I33: 577 | J33: 643 | K33: 622 | L33: 496 | M33: 200 | N33: 226 | O33: 295 | P33: 379 | Q33: 416 | R33: 463 | S33: 427 | T33: 454 | U33: 486
A34: % change | C34: =C33/B33-1 -> -0.072507553 | D34: =D33/C33-1 -> -0.33876221 | E34: =E33/D33-1 -> 0.16256158 | F34: =F33/E33-1 -> 0.30084746 | G34: =G33/F33-1 -> 0.21172638 | H34: =H33/G33-1 -> 0.39516129 | I34: =I33/H33-1 -> 0.11175337 | J34: =J33/I33-1 -> 0.11438475 | ... U34: =U33/T33-1 -> 0.070484581
A35: % of total | B35: =B33/B$45 -> 0.10660225 | C35: =C33/C$45 -> 0.099675325 | D35: =D33/D$45 -> 0.052509053 | E35: =E33/E$45 -> 0.049936521 | F35: =F33/F$45 -> 0.061363182 | G35: =G33/G$45 -> 0.065712772 | H35: =H33/H$45 -> 0.079760258 | I35: =I33/I$45 -> 0.081233282 | ... U35: =U33/U$45 -> 0.013853258
A37: Auto | B37: 163 | C37: 155 | D37: 111 | E37: 125 | F37: 145 | G37: 154 | H37: 152 | I37: 135 | J37: 125 | K37: 138 | L37: 220 | M37: 251 | N37: 294 | O37: 296 | P37: 253 | Q37: 261 | R37: 281 | S37: 329 | T37: 346 | U37: 449
A38: % change | C38: =C37/B37-1 -> -0.049079755 | D38: =D37/C37-1 -> -0.28387097 | E38: =E37/D37-1 -> 0.12612613 | F38: =F37/E37-1 -> 0.16 | G38: =G37/F37-1 -> 0.062068966 | H38: =H37/G37-1 -> -0.012987013 | I38: =I37/H37-1 -> -0.11184211 | J38: =J37/I37-1 -> -0.074074074 | ... U38: =U37/T37-1 -> 0.29768786
A39: % of total | B39: =B37/B$45 -> 0.052495974 | C39: =C37/C$45 -> 0.050324675 | D39: =D37/D$45 -> 0.028711847 | E39: =E37/E$45 -> 0.026449429 | F39: =F37/F$45 -> 0.02898261 | G39: =G37/G$45 -> 0.027203674 | H39: =H37/H$45 -> 0.023359459 | I39: =I37/I$45 -> 0.019006054 | ... U39: =U37/U$45 -> 0.012798586
A41: OEM & Other | B41: 152 | C41: 138 | D41: 146 | E41: 194 | F41: 153 | G41: 327 | H41: 409 | I41: 234 | J41: 192 | K41: 158 | L41: 140 | M41: 73 | N41: 84 | O41: 77 | P41: 66 | Q41: 73 | R41: 90 | S41: 76 | T41: 34 | U41: 47
A42: % change | C42: =C41/B41-1 -> -0.092105263 | D42: =D41/C41-1 -> 0.057971014 | E42: =E41/D41-1 -> 0.32876712 | F42: =F41/E41-1 -> -0.21134021 | G42: =G41/F41-1 -> 1.1372549 | H42: =H41/G41-1 -> 0.25076453 | I42: =I41/H41-1 -> -0.42787286 | J42: =J41/I41-1 -> -0.17948718 | ... U42: =U41/T41-1 -> 0.38235294
A43: % of total | B43: =B41/B$45 -> 0.048953301 | C43: =C41/C$45 -> 0.044805195 | D43: =D41/D$45 -> 0.037765132 | E43: =E41/E$45 -> 0.041049513 | F43: =F41/F$45 -> 0.030581651 | G43: =G41/G$45 -> 0.057763646 | H43: =H41/H$45 -> 0.062855387 | I43: =I41/I$45 -> 0.032943827 | ... U43: =U41/U$45 -> 0.0013397184
A45: Total | B45: =SUM(B25,B29,B33,B37,B41) -> 3105 | C45: =SUM(C25,C29,C33,C37,C41) -> 3080 | D45: =SUM(D25,D29,D33,D37,D41) -> 3866 | E45: =SUM(E25,E29,E33,E37,E41) -> 4726 | F45: =SUM(F25,F29,F33,F37,F41) -> 5003 | G45: =SUM(G25,G29,G33,G37,G41) -> 5661 | H45: =SUM(H25,H29,H33,H37,H41) -> 6507 | I45: =SUM(I25,I29,I33,I37,I41) -> 7103 | ... U45: =SUM(U25,U29,U33,U37,U41) -> 35082
A46: % change | C46: =C45/B45-1 -> -0.0080515298 | D46: =D45/C45-1 -> 0.25519481 | E46: =E45/D45-1 -> 0.22245215 | F46: =F45/E45-1 -> 0.058611934 | G46: =G45/F45-1 -> 0.13152109 | H46: =H45/G45-1 -> 0.14944356 | I46: =I45/H45-1 -> 0.091593668 | J46: =J45/I45-1 -> 0.076024215 | ... U46: =U45/T45-1 -> 0.16784288
A48: OEM & Other | B48: Original Equipment Manufacturers

Sheet Income Statement
A2: Income Statement
A3: All figures in millions USD (except per-share amounts)
A6: Fiscal Year | B6: Q4 2020 | C6: Q1 2021 | D6: Q2 2021 | E6: Q3 2021 | F6: Q4 2021 | G6: Q1 2022 | H6: Q2 2022 | I6: Q3 2022 | J6: Q4 2022 | K6: Q1 2023 | L6: Q2 2023 | M6: Q3 2023 | N6: Q4 2023 | O6: Q1 2024 | P6: Q2 2024 | Q6: Q3 2024 | R6: Q4 2024 | S6: Q1 2025 | T6: Q2 2025
A7: Quarterly Date | B7: 44227 | C7: 44318 | D7: 44409 | E7: 44500 | F7: 44591 | G7: 44682 | H7: 44773 | I7: 44864 | J7: 44955 | K7: 45046 | L7: 45137 | M7: 45228 | N7: 45319 | O7: 45410 | P7: 45501 | Q7: 45592 | R7: 45683 | S7: 45774 | T7: 45865
A9: Revenue | B9: 5003 | C9: 5,661 | D9: 6,507 | E9: 7103 | F9: 7643 | G9: 8288 | H9: 6,704 | I9: 5,931 | J9: 6051 | K9: 7192 | L9: 13507 | M9: 18120 | N9: 22103 | O9: 26044 | P9: 30040 | Q9: 35082 | R9: 39331 | S9: 44062 | T9: 46743
A10: Cost of revenue | B10: 1846 | C10: 2,032 | D10: 2,292 | E10: 2,472 | F10: 2643 | G10: 2857 | H10: 3,789 | I10: 2,754 | J10: 2218 | K10: 2544 | L10: 4045 | M10: 4720 | N10: 5312 | O10: 5638 | P10: 7466 | Q10: 8926 | R10: 10608 | S10: 17394 | T10: 12890
A11: Gross profit | B11: 3157 | C11: 3,629 | D11: 4,215 | E11: 4,631 | F11: 5000 | G11: 5431 | H11: 2,915 | I11: 3,177 | J11: 3833 | K11: 4648 | L11: 9462 | M11: 13400 | N11: 16791 | O11: 20406 | P11: 22574 | Q11: 26156 | R11: 28723 | S11: 26668 | T11: 33853
A13: Operating Expenses
A14: Research and development | B14: 1145 | C14: 1,153 | D14: 1,245 | E14: 1,403 | F14: 1467 | G14: 1618 | H14: 1,824 | I14: 1,945 | J14: 1952 | K14: 1875 | L14: 2040 | M14: 2294 | N14: 2466 | O14: 2720 | P14: 3090 | Q14: 3390 | R14: 3714 | S14: 3989 | T14: 4291
A15: Sales, general and administrative | B15: 505 | C15: 520 | D15: 526 | E15: 557 | F15: 563 | G15: 592 | H15: 592 | I15: 631 | J15: 625 | K15: 633 | L15: 622 | M15: 689 | N15: 710 | O15: 777 | P15: 842 | Q15: 897 | R15: 975 | S15: 1041 | T15: 1122
A16: Acquisition termination cost | B16: — | C16: — | D16: — | E16: — | F16: — | G16: 1353 | H16: — | I16: — | J16: — | K16: — | L16: — | M16: — | N16: — | O16: — | P16: — | Q16: — | R16: — | S16: — | T16: —
A17: Total operating expenses | B17: 1650 | C17: 1,673 | D17: 1,771 | E17: 1,960 | F17: 2030 | G17: 3563 | H17: 2,416 | I17: 2,576 | J17: 2577 | K17: 2508 | L17: 2662 | M17: 2983 | N17: 3176 | O17: 3497 | P17: 3932 | Q17: 4287 | R17: 4689 | S17: 5030 | T17: 5413
A19: Operating income | B19: 1507 | C19: 1,956 | D19: 2,444 | E19: 2,671 | F19: 2970 | G19: 1868 | H19: 499 | I19: 601 | J19: 1256 | K19: 2140 | L19: 6800 | M19: 10417 | N19: 13615 | O19: 16909 | P19: 18642 | Q19: 21869 | R19: 24034 | S19: 21638 | T19: 28440
A20: Interest income | B20: 7 | C20: 6 | D20: 6 | E20: 7 | F20: 10 | G20: 18 | H20: 46 | I20: 88 | J20: 115 | K20: 150 | L20: 187 | M20: 234 | N20: 295 | O20: 359 | P20: 444 | Q20: 472 | R20: 511 | S20: 515 | T20: 592
A21: Interest expense | B21: -52 | C21: -53 | D21: (60) | E21: (62) | F21: -61 | G21: -68 | H21: (65) | I21: (65) | J21: -64 | K21: -66 | L21: -65 | M21: -63 | N21: -63 | O21: -64 | P21: -61 | Q21: -61 | R21: -61 | S21: -63 | T21: -62
A22: Other income (expense), net | B22: 10 | C22: 135 | D22: 4 | E22: 22 | F22: -54 | G22: -13 | H22: (5) | I22: (11) | J22: -19 | K22: -15 | L22: 59 | M22: -66 | N22: 259 | O22: 75 | P22: 189 | Q22: 36 | R22: 733 | S22: -180 | T22: 2236
A23: Total other income (expense), net | B23: -36 | C23: 88 | D23: (50) | E23: (33) | F23: -105 | G23: -63 | H23: (24) | I23: 12 | J23: 32 | K23: 69 | L23: 181 | M23: 105 | N23: 491 | O23: 370 | P23: 249 | Q23: 447 | R23: 1183 | S23: 272 | T23: 2766
A25: Income before income tax | B25: 1471 | C25: 2,044 | D25: 2,394 | E25: 2,638 | F25: 2865 | G25: 1805 | H25: 475 | I25: 613 | J25: 1288 | K25: 2209 | L25: 6981 | M25: 10522 | N25: 14106 | O25: 17279 | P25: 19214 | Q25: 22316 | R25: 25217 | S25: 21910 | T25: 31206
A26: Income tax expense | B26: 14 | C26: 132 | D26: 20 | E26: 174 | F26: -137 | G26: 187 | H26: (181) | I26: (67) | J26: -126 | K26: 166 | L26: 793 | M26: 1279 | N26: 1820 | O26: 2398 | P26: 2615 | Q26: 3007 | R26: 3126 | S26: 3135 | T26: 4784
A27: Net income | B27: 1457 | C27: 1,912 | D27: 2,374 | E27: 2,464 | F27: 3002 | G27: 1618 | H27: 656 | I27: 680 | J27: 1414 | K27: 2043 | L27: 6188 | M27: 9243 | N27: 12286 | O27: 14881 | P27: 16599 | Q27: 19309 | R27: 22091 | S27: 18775 | T27: 26422
A29: Net income per share:
A30: Basic | B30: 2.36 | C30: 0.77 | D30: 0.95 | E30: 0.99 | F30: 1.2 | G30: 0.65 | H30: 0.26 | I30: 0.27 | J30: 0.58 | K30: 0.83 | L30: 0.25 | M30: 0.37 | N30: 4.97 | O30: 0.6 | P30: 0.68 | Q30: 0.79 | R30: 0.9 | S30: 0.77 | T30: 1.08
A31: Diluted | B31: 2.32 | C31: 0.76 | D31: 0.94 | E31: 0.97 | F31: 1.18 | G31: 0.64 | H31: 0.26 | I31: 0.27 | J31: 0.57 | K31: 0.82 | L31: 0.25 | M31: 0.37 | N31: 4.92 | O31: 0.6 | P31: 0.67 | Q31: 0.78 | R31: 0.89 | S31: 0.76 | T31: 1.08
A33: Weighted average shares used in per share:
A34: Basic | B34: 617 | C34: 2,484 | D34: 2,493 | E34: 2,499 | F34: 2,496 | G34: 2506 | H34: 2,495 | I34: 2483 | J34: 2,487 | K34: 2470 | L34: 2473 | M34: 2468 | N34: 2469 | O34: 2462 | P34: 2458 | Q34: 2453 | R34: 2449 | S34: 244 | T34: 2437
A35: Diluted | B35: 628 | C35: 2,528 | D35: 2,532 | E35: 2,538 | F35: 2,535 | G35: 2537 | H35: 2,516 | I35: 2499 | J35: 2,507 | K35: 2490 | L35: 2499 | M35: 2494 | N35: 2494 | O35: 2489 | P35: 2485 | Q35: 2477 | R35: 2471 | S35: 2461 | T35: 2453

Sheet Balance Sheet
A2: Balance Sheet
A3: All figures in millions USD (except per-share amounts)
A6: Fiscal Year | B6: Q4 2020 | C6: Q1 2021 | D6: Q2 2021 | E6: Q3 2021 | F6: Q4 2021 | G6: Q1 2022 | H6: Q2 2022 | I6: Q3 2022 | J6: Q4 2022 | K6: Q1 2023 | L6: Q2 2023 | M6: Q3 2023 | N6: Q4 2023 | O6: Q1 2024 | P6: Q2 2024 | Q6: Q3 2024 | R6: Q4 2024 | S6: Q1 2025 | T6: Q2 2025
A7: Quarterly Date | B7: 44227 | C7: 44318 | D7: 44409 | E7: 44500 | F7: 44591 | G7: 44682 | H7: 44773 | I7: 44864 | J7: 44955 | K7: 45046 | L7: 45137 | M7: 45228 | N7: 45319 | O7: 45410 | P7: 45501 | Q7: 45592 | R7: 45683 | S7: 45774 | T7: 45865
A9: Assets
A10: Current assets:
A11: Cash and cash equivalents | B11: 847 | C11: 978 | D11: 5628 | E11: 1288 | F11: 1990 | G11: 3887 | H11: 3013 | I11: 2800 | J11: 3,389 | K11: 5079 | L11: 5,783 | M11: 5519 | N11: 7280 | O11: 7587 | P11: 8571 | Q11: 9107 | R11: 8589 | S11: 15234 | T11: 11639
A12: Marketable securities | B12: 10714 | C12: 11689 | D12: 14026 | E12: 18010 | F12: 19218 | G12: 16451 | H12: 14024 | I12: 10343 | J12: 9,907 | K12: 10241 | L12: 10,240 | M12: 12762 | N12: 18704 | O12: 23851 | P12: 26229 | Q12: 29380 | R12: 34621 | S12: 38457 | T12: 45152
A13: Accounts receivable, net | B13: 2429 | C13: 3024 | D13: 3586 | E13: 3954 | F13: 4650 | G13: 5438 | H13: 5317 | I13: 4908 | J13: 3,827 | K13: 4080 | L13: 7,066 | M13: 8309 | N13: 9999 | O13: 12365 | P13: 14132 | Q13: 17693 | R13: 23065 | S13: 22132 | T13: 27808
A14: Inventories | B14: 1826 | C14: 1992 | D14: 2114 | E14: 2233 | F14: 2605 | G14: 3163 | H14: 3889 | I14: 4454 | J14: 5,159 | K14: 4611 | L14: 4,319 | M14: 4779 | N14: 5282 | O14: 5864 | P14: 6675 | Q14: 7654 | R14: 10080 | S14: 11333 | T14: 14962
A15: Prepaid expenses and other current assets | B15: 239 | C15: 444 | D15: 452 | E15: 321 | F15: 366 | G15: 636 | H15: 1175 | I15: 718 | J15: 791 | K15: 872 | L15: 1,389 | M15: 1289 | N15: 3080 | O15: 4062 | P15: 4026 | Q15: 3806 | R15: 3771 | S15: 2779 | T15: 2658
A16: Total current assets | B16: 16055 | C16: 18127 | D16: 25806 | E16: 25806 | F16: 28829 | G16: 29575 | H16: 27418 | I16: 23223 | J16: 23,073 | K16: 24883 | L16: 28,797 | M16: 32658 | N16: 44345 | O16: 53729 | P16: 59633 | Q16: 67640 | R16: 80126 | S16: 89935 | T16: 102219
A17: Property and equipment, net | B17: 2149 | C17: 2268 | D17: 2364 | E17: 2509 | F17: 2778 | G17: 2916 | H17: 3233 | I17: 3774 | J17: 3,807 | K17: 3740 | L17: 3,799 | M17: 3844 | N17: 3914 | O17: 4006 | P17: 4885 | Q17: 5343 | R17: 6283 | S17: 7136 | T17: 9141
A18: Operating lease assets | B18: 707 | C18: 727 | D18: 801 | E18: 830 | F18: 829 | G18: 856 | H18: 852 | I18: 927 | J18: 1,038 | K18: 1094 | L18: 1,235 | M18: 1316 | N18: 1346 | O18: 1532 | P18: 1556 | Q18: 1755 | R18: 1793 | S18: 1810 | T18: 2084
A19: Goodwill | B19: 4193 | C19: 4193 | D19: 4193 | E19: 4302 | F19: 4349 | G19: 4365 | H19: 4372 | I19: 4372 | J19: 4,372 | K19: 4430 | L19: 4,430 | M19: 4430 | N19: 4430 | O19: 4453 | P19: 4622 | Q19: 4724 | R19: 5188 | S19: 5498 | T19: 5755
A20: Intangible assets, net | B20: 2737 | C20: 2613 | D20: 2478 | E20: 2454 | F20: 2339 | G20: 2211 | H20: 2036 | I20: 1850 | J20: 1,676 | K20: 1541 | L20: 1,395 | M20: 1251 | N20: 1112 | O20: 986 | P20: 952 | Q20: 838 | R20: 807 | S20: 769 | T20: 755
A21: Deferred income tax assets | B21: 806 | C21: 778 | D21: 958 | E21: 970 | F21: 1222 | G21: 1784 | H21: 2225 | I21: 2762 | J21: 3,396 | K21: 4568 | L21: 5,398 | M21: 5982 | N21: 6081 | O21: 7798 | P21: 9578 | Q21: 10276 | R21: 10979 | S21: 13318 | T21: 13570
A22: Other assets | B22: 2144 | C22: 2090 | D22: 2050 | E22: 3761 | F22: 3841 | G22: 3505 | H22: 3340 | I22: 3580 | J22: 3,820 | K22: 4204 | L22: 4,501 | M22: 4667 | N22: 4500 | O22: 4568 | P22: 4001 | Q22: 5437 | R22: 6425 | S22: 6788 | T22: 7216
A23: Total assets | B23: 28791 | C23: 30796 | D23: 38650 | E23: 40632 | F23: 44187 | G23: 45212 | H23: 43476 | I23: 40488 | J23: 41,182 | K23: 44460 | L23: 49,555 | M23: 54148 | N23: 65728 | O23: 77072 | P23: 85227 | Q23: 96013 | R23: 111601 | S23: 125254 | T23: 140740
A25: Liabilities and Shareholders' Equity
A26: Current liabilities:
A27: Accounts payable | B27: 1201 | C27: 1218 | D27: 1474 | E27: 1664 | F27: 1783 | G27: 1999 | H27: 2421 | I27: 1491 | J27: 1,193 | K27: 1141 | L27: 1,929 | M27: 2380 | N27: 2699 | O27: 2715 | P27: 3680 | Q27: 5353 | R27: 6310 | S27: 7331 | T27: 9064
A28: Accrued and other current liabilities | B28: 1725 | C28: 1787 | D28: 1974 | E28: 1948 | F28: 2552 | G28: 3563 | H28: 3903 | I28: 4115 | J28: 4,120 | K28: 4869 | L28: 7,156 | M28: 5472 | N28: 6682 | O28: 11258 | P28: 10289 | Q28: 11126 | R28: 11737 | S28: 19211 | T28: 15193
A29: Short-term debt | B29: 999 | C29: 999 | D29: 1000 | E29: 0 | F29: 0 | G29: 0 | H29: 1249 | I29: 1249 | J29: 1,250 | K29: 1250 | L29: 1,249 | M29: 1249 | N29: 1250 | O29: 1250 | P29: 0 | Q29: 0 | R29: 0 | S29: 0 | T29: 0
A30: Total current liabilities | B30: 3925 | C30: 4004 | D30: 4448 | E30: 3612 | F30: 4335 | G30: 5562 | H30: 7573 | I30: 6855 | J30: 6,563 | K30: 7260 | L30: 10,334 | M30: 9101 | N30: 10631 | O30: 15223 | P30: 13969 | Q30: 16479 | R30: 18047 | S30: 26542 | T30: 24257
A31: Long-term debt | B31: 5964 | C31: 5964 | D31: 10943 | E31: 10944 | F31: 10946 | G31: 10947 | H31: 9700 | I31: 9701 | J31: 9,703 | K31: 9704 | L31: 8,456 | M31: 8457 | N31: 8459 | O31: 8460 | P31: 8461 | Q31: 8462 | R31: 8463 | S31: 8464 | T31: 8466
A32: Long-term operating lease liabilities | B32: 634 | C32: 640 | D32: 716 | E32: 743 | F32: 741 | G32: 752 | H32: 743 | I32: 798 | J32: 902 | K32: 939 | L32: 1,041 | M32: 1091 | N32: 1119 | O32: 1281 | P32: 1304 | Q32: 1490 | R32: 1519 | S32: 1521 | T32: 1831
A33: Other long-term liabilities | B33: 1375 | C33: 1414 | D33: 1396 | E33: 1535 | F33: 1553 | G33: 1631 | H33: 1609 | I33: 1785 | J33: 1,913 | K33: 2037 | L33: 2,223 | M33: 2234 | N33: 2541 | O33: 2966 | P33: 3336 | Q33: 3683 | R33: 4245 | S33: 4884 | T33: 6055
A34: Total liabilities | B34: 11898 | C34: 12022 | D34: 17503 | E34: 16834 | F34: 17575 | G34: 18892 | H34: 19625 | I34: 19139 | J34: 19,081 | K34: 19940 | L34: 22,054 | M34: 20883 | N34: 22750 | O34: 27930 | P34: 27070 | Q34: 30114 | R34: 32274 | S34: 41411 | T34: 40609
A36: Commitments and Contingencies
A37: Shareholders’ equity
A38: Preferred stock | B38: — | C38: — | D38: — | E38: — | F38: — | G38: — | H38: — | I38: — | J38: — | K38: — | L38: — | M38: — | N38: — | O38: — | P38: — | Q38: — | R38: — | S38: — | T38: —
A39: Common stock | B39: 3 | C39: 1 | D39: 3 | E39: 3 | F39: 3 | G39: 3 | H39: 2 | I39: 2 | J39: 2 | K39: 2 | L39: 2 | M39: 2 | N39: 2
A40: Additional paid-in capital | B40: 8719 | C40: 9280 | D40: 9745 | E40: 10465 | F40: 10385 | G40: 10623 | H40: 10968 | I40: 11565 | J40: 11,971 | K40: 12453 | L40: 12,629 | M40: 12991 | N40: 13132
A41: Accumulated other comprehensive loss | B41: 19 | C41: 14 | D41: 8 | E41: 9 | F41: -11 | G41: -64 | H41: -90 | I41: -123 | J41: (43) | K41: -50 | L41: (51) | M41: -88 | N41: 27
A42: Retained earnings | B42: 18908 | C42: 20721 | D42: 22995 | E42: 25359 | F42: 16235 | G42: 15758 | H42: 12971 | I42: 9905 | J42: 10,171 | K42: 12115 | L42: 14,921 | M42: 20360 | N42: 29817
A43: Total shareholders' equity | B43: 16893 | C43: 18774 | D43: 21147 | E43: 23798 | F43: 26612 | G43: 26320 | H43: 23851 | I43: 21349 | J43: 22,101 | K43: 24520 | L43: 27,501 | M43: 33265 | N43: 42978
A44: Total liabilities and shareholders' equity | B44: 28791 | C44: 30796 | D44: 38650 | E44: 40632 | F44: 44187 | G44: 45212 | H44: 43476 | I44: 40488 | J44: 41,182 | K44: 44460 | L44: 49,555 | M44: 54148 | N44: 65728

Sheet Cash Flow Statement
A2: Cash Flow Statement
A3: All figures in millions USD (except per-share amounts)
A6: Fiscal Year | B6: Q1 2021 | C6: Q2 2021 | D6: Q3 2021 | E6: Q4 2021 | F6: Q1 2022 | G6: Q2 2022 | H6: Q3 2022 | I6: Q4 2022 | J6: Q1 2023 | K6: Q2 2023 | L6: Q3 2023 | M6: Q4 2023 | N6: Q1 2024 | O6: Q2 2024 | P6: Q3 2024 | Q6: Q4 2024 | R6: Q1 2025 | S6: Q2 2025
A7: Quarterly Date | B7: 44318 | C7: 44409 | D7: 44500 | E7: 44591 | F7: 44682 | G7: 44773 | H7: 44864 | I7: 44955 | J7: 45046 | K7: 45137 | L7: 45228 | M7: 45319 | N7: 45410 | O7: 45501 | P7: 45592 | Q7: 45683 | R7: 45774 | S7: 45865
A9: Cash flows from operating activities:
A10: Net income | B10: 1912 | C10: 4285 | D10: 6749 | E10: 9752 | F10: 1618 | G10: 2274 | H10: 2954 | I10: 4368 | J10: 2043 | K10: 8232 | L10: 17475 | M10: 29760 | N10: 14881 | O10: 31480 | P10: 50789 | Q10: 72880 | R10: 18775 | S10: 45197
A11: Adjustments to reconcile net income to net cash provided by operating activities:
A12: Acquisition termination cost | B12: — | C12: — | D12: — | E12: — | F12: 1353 | G12: 1353 | H12: 1353 | I12: 1353 | J12: — | K12: — | L12: — | M12: — | N12: — | O12: — | P12: — | Q12: — | R12: — | S12: —
A13: Stock-based compensation expense | B13: 429 | C13: 894 | D13: 1453 | E13: 2004 | F13: 578 | G13: 1226 | H13: 1971 | I13: 2709 | J13: 735 | K13: 1576 | L13: 2555 | M13: 3549 | N13: 1011 | O13: 2164 | P13: 3416 | Q13: 4737 | R13: 1474 | S13: 3099
A14: Depreciation and amortization | B14: 281 | C14: 567 | D14: 865 | E14: 1174 | F14: 334 | G14: 712 | H14: 1118 | I14: 1544 | J14: 384 | K14: 749 | L14: 1121 | M14: 1508 | N14: 410 | O14: 843 | P14: 1321 | Q14: 1864 | R14: 611 | S14: 1280
A15: Deferred income taxes | B15: 24 | C15: -161 | D15: -182 | E15: -406 | F15: -542 | G15: -985 | H15: -1517 | I15: -2164 | J15: -1135 | K15: -1881 | L15: -2411 | M15: -2489 | N15: -1577 | O15: -3276 | P15: -3879 | Q15: -4477 | R15: -2177 | S15: -2160
A16: (Gains) losses on investments in non-affiliates, net | B16: -133 | C16: -133 | D16: -152 | E16: -100 | F16: 17 | G16: 24 | H16: 35 | I16: 45 | J16: 14 | K16: -45 | L16: 24 | M16: -238 | N16: -69 | O16: -264 | P16: -302 | Q16: -1030 | R16: 175 | S16: -2073
A17: Other | B17: -3 | C17: 16 | D17: 25 | E17: 47 | F17: 23 | G17: 18 | H17: -27 | I17: -7 | J17: -34 | K17: -102 | L17: -170 | M17: -278 | N17: -145 | O17: -288 | P17: -365 | Q17: -502 | R17: -98 | S17: -196
A18: Changes in operating assets and liabilities, net of acquisitions:
A19: Accounts receivable | B19: -595 | C19: -1157 | D19: -1523 | E19: -2215 | F19: -788 | G19: -668 | H19: -258 | I19: 822 | J19: -252 | K19: -3239 | L19: -4482 | M19: -6172 | N19: -2366 | O19: -4133 | P19: -7694 | Q19: -13063 | R19: 933 | S19: -4743
A20: Inventories | B20: -159 | C20: -282 | D20: -400 | E20: -774 | F20: -560 | G20: -1285 | H20: -1848 | I20: -2554 | J20: 566 | K20: 861 | L20: 405 | M20: -98 | N20: -577 | O20: -1380 | P20: -2357 | Q20: -4781 | R20: -1258 | S20: -4880
A21: Prepaid expenses and other assets | B21: 2 | C21: 18 | D21: -1557 | E21: -1715 | F21: -1261 | G21: -1554 | H21: -1307 | I21: -1517 | J21: -215 | K21: -592 | L21: -337 | M21: -1522 | N21: -726 | O21: -12 | P21: -726 | Q21: -395 | R21: 560 | S21: 946
A22: Accounts payable | B22: 36 | C22: 245 | D22: 474 | E22: 568 | F22: 255 | G22: 559 | H22: -358 | I22: -551 | J22: 11 | K22: 789 | L22: 1250 | M22: 1531 | N22: -22 | O22: 801 | P22: 2490 | Q22: 3357 | R22: 941 | S22: 2255
A23: Accrued and other current liabilities | B23: 33 | C23: 166 | D23: 70 | E23: 581 | F23: 634 | G23: 1267 | H23: 1175 | I23: 1341 | J23: 689 | K23: 2675 | L23: 953 | M23: 2025 | N23: 4202 | O23: 3314 | P23: 3918 | Q23: 4278 | R23: 7128 | S23: 3075
A24: Other long-term liabilities | B24: 47 | C24: 98 | D24: 253 | E24: 192 | F24: 70 | G24: 60 | H24: 102 | I24: 252 | J24: 105 | K24: 236 | L24: 208 | M24: 514 | N24: 323 | O24: 584 | P24: 349 | Q24: 1221 | R24: 350 | S24: 979
A25: Net cash provided by operating activities | B25: 1874 | C25: 4556 | D25: 6075 | E25: 9108 | F25: 1731 | G25: 3001 | H25: 3393 | I25: 5641 | J25: 2911 | K25: 9259 | L25: 16591 | M25: 28090 | N25: 15345 | O25: 29833 | P25: 47460 | Q25: 64089 | R25: 27414 | S25: 42779
A27: Cash flows from investing activities:
A28: Proceeds from maturities of marketable securities | B28: 3140 | C28: 5236 | D28: 7780 | E28: 15197 | F28: 5947 | G28: 10983 | H28: 16792 | I28: 19425 | J28: 2512 | K28: 5111 | L28: 8001 | M28: 9732 | N28: 4004 | O28: 8098 | P28: 9485 | Q28: 11195 | R28: 3122 | S28: 6252
A29: Proceeds from sales of marketable securities | B29: 358 | C29: 705 | D29: 916 | E29: 1023 | F29: 1029 | G29: 1731 | H29: 1806 | I29: 1806 | J29: — | K29: — | L29: — | M29: 50 | N29: 149 | O29: 164 | P29: 318 | Q29: 495 | R29: 467 | S29: 487
A30: Purchases of marketable securities | B30: -4470 | C30: -9268 | D30: -16020 | E30: -24787 | F30: -3932 | G30: -7576 | H30: -9764 | I30: -11897 | J30: -2801 | K30: -5343 | L30: -10688 | M30: -18211 | N30: -9303 | O30: -15047 | P30: -19565 | Q30: -26575 | R30: -6546 | S30: -14358
A31: Purchases related to property and equipment and intangible assets | B31: -298 | C31: -481 | D31: -703 | E31: -976 | F31: -361 | G31: -794 | H31: -1324 | I31: -1833 | J31: -248 | K31: -537 | L31: -815 | M31: -1069 | N31: -369 | O31: -1346 | P31: -2159 | Q31: -3236 | R31: -1227 | S31: -3122
A32: Investments and other, net | B32: -2 | C32: 3 | D32: -203 | E32: -24 | F32: -36 | G32: -49 | H32: -49 | I32: -49 | J32: -221 | K32: -435 | L32: -872 | M32: -985 | N32: -135 | O32: -429 | P32: -837 | Q32: -456 | R32: -649 | S32: -995
A33: Acquisitions, net of cash acquired | B33: — | C33: — | D33: -14 | E33: -263 | F33: -35 | G33: -65 | H33: -83 | I33: -77 | J33: -83 | K33: -83 | L33: -83 | M33: -83 | N33: -39 | O33: -317 | P33: -465 | Q33: -1007 | R33: -383 | S33: -677
A34: Net cash used in investing activities | B34: -1272 | C34: -3805 | D34: -8244 | E34: -9830 | F34: 2612 | G34: 4230 | H34: 7378 | I34: 7375 | J34: -841 | K34: -1287 | L34: -4457 | M34: -10566 | N34: -5693 | O34: -8877 | P34: -13223 | Q34: -20421 | R34: -5216 | S34: -12343
A36: Cash flows from financing activities:
A37: Issuance of debt, net of issuance costs | B37: — | C37: 4985 | D37: 4977 | E37: 4977 | F37: — | G37: — | H37: — | I37: — | J37: — | K37: — | L37: — | M37: — | N37: — | O37: — | P37: — | Q37: — | R37: — | S37: —
A38: Proceeds related to employee stock plans | B38: 126 | C38: 128 | D38: 277 | E38: 281 | F38: 204 | G38: 205 | H38: 349 | I38: 355 | J38: 246 | K38: 247 | L38: 403 | M38: 403 | N38: 285 | O38: 285 | P38: 489 | Q38: 490 | R38: 370 | S38: 370
A39: Payments related to repurchases of common stock | B39: — | C39: — | D39: — | E39: — | F39: -1996 | G39: -5341 | H39: -8826 | I39: -10039 | J39: — | K39: -3067 | L39: -6874 | M39: -9533 | N39: -7740 | O39: -14898 | P39: -25895 | Q39: -33706 | R39: -14095 | S39: -23815
A40: Payments related to tax on restricted stock units | B40: -477 | C40: -843 | D40: -1282 | E40: -1904 | F40: -532 | G40: -837 | H40: -1131 | I40: -1475 | J40: -507 | K40: -1179 | L40: -1942 | M40: -2783 | N40: -1752 | O40: -3389 | P40: -5068 | Q40: -6930 | R40: -1532 | S40: -3380
A41: Dividends paid | B41: -99 | C41: -198 | D41: -298 | E41: -399 | F41: -100 | G41: -200 | H41: -300 | I41: -398 | J41: -99 | K41: -199 | L41: -296 | M41: -395 | N41: -98 | O41: -344 | P41: -589 | Q41: -834 | R41: -244 | S41: -488
A42: Principal payments on property and equipment | B42: -19 | C42: -40 | D42: -62 | F42: -22 | G42: -36 | H42: -54 | I42: -58 | J42: -20 | K42: -31 | L42: -44 | M42: -74 | N42: -40 | O42: -69 | P42: -97 | Q42: -129 | R42: -52 | S42: -73
A43: Repayment of debt | B43: — | C43: — | D43: -1000 | E43: -1000 | F43: — | G43: — | H43: — | I43: — | J43: — | K43: -1250 | L43: -1250 | M43: -1250 | N43: — | O43: -1250 | P43: — | Q43: -1250 | R43: — | S43: —
A44: Other | B44: -2 | C44: -2 | D44: -2 | E44: -7 | F44: — | G44: 1 | H44: 1 | I44: -2 | J44: — | K44: — | L44: -1 | M44: -1 | N44: — | O44: — | P44: — | Q44: — | R44: — | S44: —
A45: Net cash provided by (used in) financing activities | B45: -471 | C45: 4030 | D45: 2610 | E45: 1865 | F45: -2446 | G45: -6208 | H45: -9961 | I45: -11617 | J45: -380 | K45: -5479 | L45: -10004 | M45: -13633 | N45: -9345 | O45: -19665 | P45: -32410 | Q45: -42359 | R45: -15553 | S45: -27386
A47: Change in cash and cash equivalents | B47: 131 | C47: 4781 | D47: 441 | E47: 1143 | F47: 1897 | G47: 1023 | H47: 810 | I47: 1399 | J47: 1690 | K47: 2493 | L47: 2130 | M47: 3891 | N47: 307 | O47: 1291 | P47: 1827 | Q47: 1309 | R47: 6645 | S47: 3050
...

Sheet Working Capital
A2: Working Capital Schedule
D4: Historical | W4: Projected
A5: $ in millions | D5: Q4 2021 | E5: Q1 2022 | F5: =IF(MID(E5,2,1)="4","Q1 "&RIGHT(E5,4)+1, "Q"&MID(E5,2,1)+1&" "&RIGHT(E5,4)) -> Q2 2022 | G5: =IF(MID(F5,2,1)="4","Q1 "&RIGHT(F5,4)+1, "Q"&MID(F5,2,1)+1&" "&RIGHT(F5,4)) -> Q3 2022 | H5: =IF(MID(G5,2,1)="4","Q1 "&RIGHT(G5,4)+1, "Q"&MID(G5,2,1)+1&" "&RIGHT(G5,4)) -> Q4 2022 | I5: =IF(MID(H5,2,1)="4","Q1 "&RIGHT(H5,4)+1, "Q"&MID(H5,2,1)+1&" "&RIGHT(H5,4)) -> Q1 2023 | J5: =IF(MID(I5,2,1)="4","Q1 "&RIGHT(I5,4)+1, "Q"&MID(I5,2,1)+1&" "&RIGHT(I5,4)) -> Q2 2023 | K5: =IF(MID(J5,2,1)="4","Q1 "&RIGHT(J5,4)+1, "Q"&MID(J5,2,1)+1&" "&RIGHT(J5,4)) -> Q3 2023 | L5: =IF(MID(K5,2,1)="4","Q1 "&RIGHT(K5,4)+1, "Q"&MID(K5,2,1)+1&" "&RIGHT(K5,4)) -> Q4 2023 | M5: =IF(MID(L5,2,1)="4","Q1 "&RIGHT(L5,4)+1, "Q"&MID(L5,2,1)+1&" "&RIGHT(L5,4)) -> Q1 2024 | ... AF5: =IF(MID(AE5,2,1)="4","Q1 "&RIGHT(AE5,4)+1, "Q"&MID(AE5,2,1)+1&" "&RIGHT(AE5,4)) -> Q4 2028
A6: Current assets
A7: Accounts Receivables | D7: ='Balance Sheet'!B13 -> 2429 | E7: ='Balance Sheet'!C13 -> 3024 | F7: ='Balance Sheet'!D13 -> 3586 | G7: ='Balance Sheet'!E13 -> 3954 | H7: ='Balance Sheet'!F13 -> 4650 | I7: ='Balance Sheet'!G13 -> 5438 | J7: ='Balance Sheet'!H13 -> 5317 | K7: ='Balance Sheet'!I13 -> 4908 | ... V7: ='Balance Sheet'!T13 -> 27808 | W7: =(W20/90)*'DCF Valuation'!X$10 -> 22596.662 | X7: =(X20/90)*'DCF Valuation'!Y$10 -> 22898.681 | Y7: =(Y20/90)*'DCF Valuation'!Z$10 -> 26792.062 | Z7: =(Z20/90)*'DCF Valuation'!AA$10 -> 31346.646 | AA7: =(AA20/90)*'DCF Valuation'!AB$10 -> 37152.18 | AB7: =(AB20/90)*'DCF Valuation'!AC$10 -> 43751.348 | AC7: =(AC20/90)*'DCF Valuation'!AD$10 -> 53778.959 | AD7: =(AD20/90)*'DCF Valuation'!AE$10 -> 66342.77 | ... AF7: =(AF20/90)*'DCF Valuation'!AG$10 -> 100665.31
A8: Inventories | D8: ='Balance Sheet'!B14 -> 1826 | E8: ='Balance Sheet'!C14 -> 1992 | F8: ='Balance Sheet'!D14 -> 2114 | G8: ='Balance Sheet'!E14 -> 2233 | H8: ='Balance Sheet'!F14 -> 2605 | I8: ='Balance Sheet'!G14 -> 3163 | J8: ='Balance Sheet'!H14 -> 3889 | K8: ='Balance Sheet'!I14 -> 4454 | ... V8: ='Balance Sheet'!T14 -> 14962 | W8: =(W21/90)*('DCF Valuation'!X$10-'DCF Valuation'!X$13) -> 10504.652 | X8: =(X21/90)*('DCF Valuation'!Y$10-'DCF Valuation'!Y$13) -> 13414.885 | Y8: =(Y21/90)*('DCF Valuation'!Z$10-'DCF Valuation'!Z$13) -> 15466.739 | Z8: =(Z21/90)*('DCF Valuation'!AA$10-'DCF Valuation'!AA$13) -> 18541.15 | AA8: =(AA21/90)*('DCF Valuation'!AB$10-'DCF Valuation'!AB$13) -> 20144.947 | AB8: =(AB21/90)*('DCF Valuation'!AC$10-'DCF Valuation'!AC$13) -> 24276.404 | AC8: =(AC21/90)*('DCF Valuation'!AD$10-'DCF Valuation'!AD$13) -> 30880.417 | AD8: =(AD21/90)*('DCF Valuation'!AE$10-'DCF Valuation'!AE$13) -> 37581.116 | ... AF8: =(AF21/90)*('DCF Valuation'!AG$10-'DCF Valuation'!AG$13) -> 56316.674
A9: Prepaid expenses and other current assets | D9: ='Balance Sheet'!B15 -> 239 | E9: ='Balance Sheet'!C15 -> 444 | F9: ='Balance Sheet'!D15 -> 452 | G9: ='Balance Sheet'!E15 -> 321 | H9: ='Balance Sheet'!F15 -> 366 | I9: ='Balance Sheet'!G15 -> 636 | J9: ='Balance Sheet'!H15 -> 1175 | K9: ='Balance Sheet'!I15 -> 718 | ... V9: ='Balance Sheet'!T15 -> 2658 | W9: =W22*'DCF Valuation'!X$10 -> 4053.7616 | X9: =X22*'DCF Valuation'!Y$10 -> 4107.9428 | Y9: =Y22*'DCF Valuation'!Z$10 -> 4806.4017 | Z9: =Z22*'DCF Valuation'!AA$10 -> 5623.478 | AA9: =AA22*'DCF Valuation'!AB$10 -> 6664.9704 | AB9: =AB22*'DCF Valuation'!AC$10 -> 7848.838 | AC9: =AC22*'DCF Valuation'!AD$10 -> 9647.7562 | AD9: =AD22*'DCF Valuation'!AE$10 -> 11901.66 | ... AF9: =AF22*'DCF Valuation'!AG$10 -> 18059.002
A10: Total current assets | D10: =D7+D8+D9 -> 4494 | E10: =E7+E8+E9 -> 5460 | F10: =F7+F8+F9 -> 6152 | G10: =G7+G8+G9 -> 6508 | H10: =H7+H8+H9 -> 7621 | I10: =I7+I8+I9 -> 9237 | J10: =J7+J8+J9 -> 10381 | K10: =K7+K8+K9 -> 10080 | ... AF10: =AF7+AF8+AF9 -> 175040.98
A12: Current liabilities
A13: Accounts Payables | D13: ='Balance Sheet'!B27 -> 1201 | E13: ='Balance Sheet'!C27 -> 1218 | F13: ='Balance Sheet'!D27 -> 1474 | G13: ='Balance Sheet'!E27 -> 1664 | H13: ='Balance Sheet'!F27 -> 1783 | I13: ='Balance Sheet'!G27 -> 1999 | J13: ='Balance Sheet'!H27 -> 2421 | K13: ='Balance Sheet'!I27 -> 1491 | ... V13: ='Balance Sheet'!T27 -> 9064 | W13: =(W23/90)*('DCF Valuation'!X$10-'DCF Valuation'!X$13) -> 5291.2428 | X13: =(X23/90)*('DCF Valuation'!Y$10-'DCF Valuation'!Y$13) -> 6757.1407 | Y13: =(Y23/90)*('DCF Valuation'!Z$10-'DCF Valuation'!Z$13) -> 7790.6691 | Z13: =(Z23/90)*('DCF Valuation'!AA$10-'DCF Valuation'!AA$13) -> 9339.2647 | AA13: =(AA23/90)*('DCF Valuation'!AB$10-'DCF Valuation'!AB$13) -> 10147.105 | AB13: =(AB23/90)*('DCF Valuation'!AC$10-'DCF Valuation'!AC$13) -> 12228.139 | AC13: =(AC23/90)*('DCF Valuation'!AD$10-'DCF Valuation'!AD$13) -> 15554.612 | AD13: =(AD23/90)*('DCF Valuation'!AE$10-'DCF Valuation'!AE$13) -> 18929.785 | ... AF13: =(AF23/90)*('DCF Valuation'!AG$10-'DCF Valuation'!AG$13) -> 28366.974
A14: Accrued and other current liabilities | D14: ='Balance Sheet'!B28 -> 1725 | E14: ='Balance Sheet'!C28 -> 1787 | F14: ='Balance Sheet'!D28 -> 1974 | G14: ='Balance Sheet'!E28 -> 1948 | H14: ='Balance Sheet'!F28 -> 2552 | I14: ='Balance Sheet'!G28 -> 3563 | J14: ='Balance Sheet'!H28 -> 3903 | K14: ='Balance Sheet'!I28 -> 4115 | ... V14: ='Balance Sheet'!T28 -> 15193 | W14: =W24*('DCF Valuation'!X$13-'DCF Valuation'!X$16) -> 7588.8381 | X14: =X24*('DCF Valuation'!Y$13-'DCF Valuation'!Y$16) -> 7588.8381 | Y14: =Y24*('DCF Valuation'!Z$13-'DCF Valuation'!Z$16) -> 7588.8381 | Z14: =Z24*('DCF Valuation'!AA$13-'DCF Valuation'!AA$16) -> 7588.8381 | AA14: =AA24*('DCF Valuation'!AB$13-'DCF Valuation'!AB$16) -> 7588.8381 | AB14: =AB24*('DCF Valuation'!AC$13-'DCF Valuation'!AC$16) -> 7588.8381 | AC14: =AC24*('DCF Valuation'!AD$13-'DCF Valuation'!AD$16) -> 7588.8381 | AD14: =AD24*('DCF Valuation'!AE$13-'DCF Valuation'!AE$16) -> 7588.8381 | ... AF14: =AF24*('DCF Valuation'!AG$13-'DCF Valuation'!AG$16) -> 7588.8381
A15: Total current liabilities | D15: =D13+D14 -> 2926 | E15: =E13+E14 -> 3005 | F15: =F13+F14 -> 3448 | G15: =G13+G14 -> 3612 | H15: =H13+H14 -> 4335 | I15: =I13+I14 -> 5562 | J15: =J13+J14 -> 6324 | K15: =K13+K14 -> 5606 | ... AF15: =AF13+AF14 -> 35955.812
A17: Net Working capital | D17: =D10-D15 -> 1568 | E17: =E10-E15 -> 2455 | F17: =F10-F15 -> 2704 | G17: =G10-G15 -> 2896 | H17: =H10-H15 -> 3286 | I17: =I10-I15 -> 3675 | J17: =J10-J15 -> 4057 | K17: =K10-K15 -> 4474 | ... AF17: =AF10-AF15 -> 139085.17
A18: Changes in working capital | E18: =E17-D17 -> 887 | F18: =F17-E17 -> 249 | G18: =G17-F17 -> 192 | H18: =H17-G17 -> 390 | I18: =I17-H17 -> 389 | J18: =J17-I17 -> 382 | K18: =K17-J17 -> 417 | L18: =L17-K17 -> -10 | ... AF18: =AF17-AE17 -> 27169.625
A20: Days Sales Outstanding (DSO) | E20: =(AVERAGE(E7,D7)/'DCF Valuation'!F10)*90 -> 43.346582 | F20: =(AVERAGE(F7,E7)/'DCF Valuation'!G10)*90 -> 45.71231 | G20: =(AVERAGE(G7,F7)/'DCF Valuation'!H10)*90 -> 47.768549 | H20: =(AVERAGE(H7,G7)/'DCF Valuation'!I10)*90 -> 50.658119 | I20: =(AVERAGE(I7,H7)/'DCF Valuation'!J10)*90 -> 54.773166 | J20: =(AVERAGE(J7,I7)/'DCF Valuation'!K10)*90 -> 72.191975 | K20: =(AVERAGE(K7,J7)/'DCF Valuation'!L10)*90 -> 77.579666 | L20: =(AVERAGE(L7,K7)/'DCF Valuation'!M10)*90 -> 72.999504 | ... P20: =(AVERAGE(P7,O7)/'DCF Valuation'!Q10)*90 -> 37.273673 | Q20: =(AVERAGE(Q7,P7)/'DCF Valuation'!X10)*90 -> 21.21598 | R20: =(AVERAGE(R7,Q7)/'DCF Valuation'!Y10)*90 -> 24.80528 | S20: =(AVERAGE(S7,R7)/'DCF Valuation'!Z10)*90 -> 25.463621 | T20: =(AVERAGE(T7,S7)/'DCF Valuation'!AA10)*90 -> 27.872741 | U20: =(AVERAGE(U7,T7)/'DCF Valuation'!AB10)*90 -> 26.078536 | V20: =(AVERAGE(V7,U7)/'DCF Valuation'!AC10)*90 -> 24.468931 | W20: =AVERAGE($E20:$V20) -> 42.873396 | X20: =AVERAGE($E20:$V20) -> 42.873396 | Y20: =AVERAGE($E20:$V20) -> 42.873396 | Z20: =AVERAGE($E20:$V20) -> 42.873396 | AA20: =AVERAGE($E20:$V20) -> 42.873396 | AB20: =AVERAGE($E20:$V20) -> 42.873396 | AC20: =AVERAGE($E20:$V20) -> 42.873396 | AD20: =AVERAGE($E20:$V20) -> 42.873396 | ... AF20: =AVERAGE($E20:$V20) -> 42.873396
A21: Days Inventory Outstanding (DIO) | E21: =(AVERAGE(E8,D8)/('DCF Valuation'!F10-'DCF Valuation'!F13))*90 -> 84.552165 | F21: =(AVERAGE(F8,E8)/('DCF Valuation'!G10-'DCF Valuation'!G13))*90 -> 80.615183 | G21: =(AVERAGE(G8,F8)/('DCF Valuation'!H10-'DCF Valuation'!H13))*90 -> 79.132282 | H21: =(AVERAGE(H8,G8)/('DCF Valuation'!I10-'DCF Valuation'!I13))*90 -> 82.372304 | I21: =(AVERAGE(I8,H8)/('DCF Valuation'!J10-'DCF Valuation'!J13))*90 -> 90.850543 | J21: =(AVERAGE(J8,I8)/('DCF Valuation'!K10-'DCF Valuation'!K13))*90 -> 83.752969 | K21: =(AVERAGE(K8,J8)/('DCF Valuation'!L10-'DCF Valuation'!L13))*90 -> 136.32353 | L21: =(AVERAGE(L8,K8)/('DCF Valuation'!M10-'DCF Valuation'!M13))*90 -> 180.73039 | ... P21: =(AVERAGE(P8,O8)/('DCF Valuation'!Q10-'DCF Valuation'!Q13))*90 -> 85.23061 | Q21: =(AVERAGE(Q8,P8)/('DCF Valuation'!X10-'DCF Valuation'!X13))*90 -> 44.61535 | R21: =(AVERAGE(R8,Q8)/('DCF Valuation'!Y10-'DCF Valuation'!Y13))*90 -> 39.302746 | S21: =(AVERAGE(S8,R8)/('DCF Valuation'!Z10-'DCF Valuation'!Z13))*90 -> 38.955078 | T21: =(AVERAGE(T8,S8)/('DCF Valuation'!AA10-'DCF Valuation'!AA13))*90 -> 40.217676 | U21: =(AVERAGE(U8,T8)/('DCF Valuation'!AB10-'DCF Valuation'!AB13))*90 -> 44.694937 | V21: =(AVERAGE(V8,U8)/('DCF Valuation'!AC10-'DCF Valuation'!AC13))*90 -> 45.544482 | W21: =AVERAGE($E21:$V21) -> 84.096309 | X21: =AVERAGE($E21:$V21) -> 84.096309 | Y21: =AVERAGE($E21:$V21) -> 84.096309 | Z21: =AVERAGE($E21:$V21) -> 84.096309 | AA21: =AVERAGE($E21:$V21) -> 84.096309 | AB21: =AVERAGE($E21:$V21) -> 84.096309 | AC21: =AVERAGE($E21:$V21) -> 84.096309 | AD21: =AVERAGE($E21:$V21) -> 84.096309 | ... AF21: =AVERAGE($E21:$V21) -> 84.096309
A22: Other current assets (% of revenue) | E22: =E9/'DCF Valuation'!F10 -> 0.078431373 | F22: =F9/'DCF Valuation'!G10 -> 0.069463655 | G22: =G9/'DCF Valuation'!H10 -> 0.045192172 | H22: =H9/'DCF Valuation'!I10 -> 0.047886955 | I22: =I9/'DCF Valuation'!J10 -> 0.076737452 | J22: =J9/'DCF Valuation'!K10 -> 0.1752685 | K22: =K9/'DCF Valuation'!L10 -> 0.12105884 | L22: =L9/'DCF Valuation'!M10 -> 0.13072219 | ... P22: =P9/'DCF Valuation'!Q10 -> 0.1393476 | Q22: =Q9/'DCF Valuation'!X10 -> 0.085632971 | R22: =R9/'DCF Valuation'!Y10 -> 0.083754603 | S22: =S9/'DCF Valuation'!Z10 -> 0.067671847 | T22: =T9/'DCF Valuation'!AA10 -> 0.057307418 | U22: =U9/'DCF Valuation'!AB10 -> 0.035632773 | V22: =V9/'DCF Valuation'!AC10 -> 0.028940692 | W22: =AVERAGE($E22:$V22) -> 0.085459295 | X22: =AVERAGE($E22:$V22) -> 0.085459295 | Y22: =AVERAGE($E22:$V22) -> 0.085459295 | Z22: =AVERAGE($E22:$V22) -> 0.085459295 | AA22: =AVERAGE($E22:$V22) -> 0.085459295 | AB22: =AVERAGE($E22:$V22) -> 0.085459295 | AC22: =AVERAGE($E22:$V22) -> 0.085459295 | AD22: =AVERAGE($E22:$V22) -> 0.085459295 | ... AF22: =AVERAGE($E22:$V22) -> 0.085459295
A23: Days Payable Outstanding (DPO) | E23: =(AVERAGE(E13,D13)/('DCF Valuation'!F10-'DCF Valuation'!F13))*90 -> 53.570374 | F23: =(AVERAGE(F13,E13)/('DCF Valuation'!G10-'DCF Valuation'!G13))*90 -> 52.853403 | G23: =(AVERAGE(G13,F13)/('DCF Valuation'!H10-'DCF Valuation'!H13))*90 -> 57.123786 | H23: =(AVERAGE(H13,G13)/('DCF Valuation'!I10-'DCF Valuation'!I13))*90 -> 58.68899 | I23: =(AVERAGE(I13,H13)/('DCF Valuation'!J10-'DCF Valuation'!J13))*90 -> 59.569478 | J23: =(AVERAGE(J13,I13)/('DCF Valuation'!K10-'DCF Valuation'!K13))*90 -> 52.494062 | K23: =(AVERAGE(K13,J13)/('DCF Valuation'!L10-'DCF Valuation'!L13))*90 -> 63.921569 | L23: =(AVERAGE(L13,K13)/('DCF Valuation'!M10-'DCF Valuation'!M13))*90 -> 60.500451 | ... P23: =(AVERAGE(P13,O13)/('DCF Valuation'!Q10-'DCF Valuation'!Q13))*90 -> 43.026167 | Q23: =(AVERAGE(Q13,P13)/('DCF Valuation'!X10-'DCF Valuation'!X13))*90 -> 21.671228 | R23: =(AVERAGE(R13,Q13)/('DCF Valuation'!Y10-'DCF Valuation'!Y13))*90 -> 20.044745 | S23: =(AVERAGE(S13,R13)/('DCF Valuation'!Z10-'DCF Valuation'!Z13))*90 -> 24.557277 | T23: =(AVERAGE(T13,S13)/('DCF Valuation'!AA10-'DCF Valuation'!AA13))*90 -> 26.449687 | U23: =(AVERAGE(U13,T13)/('DCF Valuation'!AB10-'DCF Valuation'!AB13))*90 -> 28.472593 | V23: =(AVERAGE(V13,U13)/('DCF Valuation'!AC10-'DCF Valuation'!AC13))*90 -> 28.397101 | W23: =AVERAGE($E23:$V23) -> 42.359707 | X23: =AVERAGE($E23:$V23) -> 42.359707 | Y23: =AVERAGE($E23:$V23) -> 42.359707 | Z23: =AVERAGE($E23:$V23) -> 42.359707 | AA23: =AVERAGE($E23:$V23) -> 42.359707 | AB23: =AVERAGE($E23:$V23) -> 42.359707 | AC23: =AVERAGE($E23:$V23) -> 42.359707 | AD23: =AVERAGE($E23:$V23) -> 42.359707 | ... AF23: =AVERAGE($E23:$V23) -> 42.359707
A24: Accrued and other current liabilities | E24: =E14/'Income Statement'!B17 -> 1.0830303 | F24: =F14/'Income Statement'!C17 -> 1.1799163 | G24: =G14/'Income Statement'!D17 -> 1.0999435 | H24: =H14/'Income Statement'!E17 -> 1.3020408 | I24: =I14/'Income Statement'!F17 -> 1.7551724 | J24: =J14/'Income Statement'!G17 -> 1.0954252 | K24: =K14/'Income Statement'!H17 -> 1.7032285 | L24: =L14/'Income Statement'!I17 -> 1.5993789 | ... V24: =V14/'Income Statement'!S17 -> 3.0204771 | W24: =AVERAGE($E24:$V24) -> 2.1682395 | X24: =AVERAGE($E24:$V24) -> 2.1682395 | Y24: =AVERAGE($E24:$V24) -> 2.1682395 | Z24: =AVERAGE($E24:$V24) -> 2.1682395 | AA24: =AVERAGE($E24:$V24) -> 2.1682395 | AB24: =AVERAGE($E24:$V24) -> 2.1682395 | AC24: =AVERAGE($E24:$V24) -> 2.1682395 | AD24: =AVERAGE($E24:$V24) -> 2.1682395 | ... AF24: =AVERAGE($E24:$V24) -> 2.1682395
A25: (% of operating expenses)
A26: Cash Conversion Cycle (CCC) | E26: =E21+E20-E23 -> 74.328373 | F26: =F21+F20-F23 -> 73.47409 | G26: =G21+G20-G23 -> 69.777044 | H26: =H21+H20-H23 -> 74.341433 | I26: =I21+I20-I23 -> 86.05423 | J26: =J21+J20-J23 -> 103.45088 | K26: =K21+K20-K23 -> 149.98163 | L26: =L21+L20-L23 -> 193.22944 | ... V26: =V21+V20-V23 -> 41.616311 | W26: =AVERAGE($E26:$V26) -> 84.609998 | X26: =AVERAGE($E26:$V26) -> 84.609998 | Y26: =AVERAGE($E26:$V26) -> 84.609998 | Z26: =AVERAGE($E26:$V26) -> 84.609998 | AA26: =AVERAGE($E26:$V26) -> 84.609998 | AB26: =AVERAGE($E26:$V26) -> 84.609998 | AC26: =AVERAGE($E26:$V26) -> 84.609998 | AD26: =AVERAGE($E26:$V26) -> 84.609998 | ... AF26: =AVERAGE($E26:$V26) -> 84.609998

Sheet Debt
A2: Debt Schedule
D4: Historical | V4: Projected
A5: $ in millions | D5: Q1 2022 | E5: =IF(MID(D5,2,1)="4","Q1 "&RIGHT(D5,4)+1, "Q"&MID(D5,2,1)+1&" "&RIGHT(D5,4)) -> Q2 2022 | F5: =IF(MID(E5,2,1)="4","Q1 "&RIGHT(E5,4)+1, "Q"&MID(E5,2,1)+1&" "&RIGHT(E5,4)) -> Q3 2022 | G5: =IF(MID(F5,2,1)="4","Q1 "&RIGHT(F5,4)+1, "Q"&MID(F5,2,1)+1&" "&RIGHT(F5,4)) -> Q4 2022 | H5: =IF(MID(G5,2,1)="4","Q1 "&RIGHT(G5,4)+1, "Q"&MID(G5,2,1)+1&" "&RIGHT(G5,4)) -> Q1 2023 | I5: =IF(MID(H5,2,1)="4","Q1 "&RIGHT(H5,4)+1, "Q"&MID(H5,2,1)+1&" "&RIGHT(H5,4)) -> Q2 2023 | J5: =IF(MID(I5,2,1)="4","Q1 "&RIGHT(I5,4)+1, "Q"&MID(I5,2,1)+1&" "&RIGHT(I5,4)) -> Q3 2023 | K5: =IF(MID(J5,2,1)="4","Q1 "&RIGHT(J5,4)+1, "Q"&MID(J5,2,1)+1&" "&RIGHT(J5,4)) -> Q4 2023 | L5: =IF(MID(K5,2,1)="4","Q1 "&RIGHT(K5,4)+1, "Q"&MID(K5,2,1)+1&" "&RIGHT(K5,4)) -> Q1 2024 | ... AE5: =IF(MID(AD5,2,1)="4","Q1 "&RIGHT(AD5,4)+1, "Q"&MID(AD5,2,1)+1&" "&RIGHT(AD5,4)) -> Q4 2028
A6: Opening balance | D6: ='Balance Sheet'!B29+'Balance Sheet'!B31 -> 6963 | E6: ='Balance Sheet'!C29+'Balance Sheet'!C31 -> 6963 | F6: ='Balance Sheet'!D29+'Balance Sheet'!D31 -> 11943 | G6: ='Balance Sheet'!E29+'Balance Sheet'!E31 -> 10944 | H6: ='Balance Sheet'!F29+'Balance Sheet'!F31 -> 10946 | I6: ='Balance Sheet'!G29+'Balance Sheet'!G31 -> 10947 | J6: ='Balance Sheet'!H29+'Balance Sheet'!H31 -> 10949 | K6: ='Balance Sheet'!I29+'Balance Sheet'!I31 -> 10950 | ... U6: ='Balance Sheet'!S29+'Balance Sheet'!S31 -> 8464 | V6: =U8 -> 8466 | W6: =V8 -> 8467 | X6: =W8 -> 7218 | Y6: =X8 -> 7219 | Z6: =Y8 -> 7220 | AA6: =Z8 -> 7221 | AB6: =AA8 -> 7222 | AC6: =AB8 -> 7223 | ... AE6: =AD8 -> 7225
A7: Add/Less: Debt incurred (repaid) | D7: =D8-D6 -> 0 | E7: =E8-E6 -> 4980 | F7: =F8-F6 -> -999 | G7: =G8-G6 -> 2 | H7: =H8-H6 -> 1 | I7: =I8-I6 -> 2 | J7: =J8-J6 -> 1 | K7: =K8-K6 -> 3 | ... U7: =U8-U6 -> 2 | V7: 1 | W7: -1249 | X7: 1 | Y7: 1 | Z7: 1 | AA7: 1 | AB7: 1 | AC7: 1 | AD7: 1 | AE7: 1
A8: Closing Balance | C8: ='Balance Sheet'!B29+'Balance Sheet'!B31 -> 6963 | D8: ='Balance Sheet'!C29+'Balance Sheet'!C31 -> 6963 | E8: ='Balance Sheet'!D29+'Balance Sheet'!D31 -> 11943 | F8: ='Balance Sheet'!E29+'Balance Sheet'!E31 -> 10944 | G8: ='Balance Sheet'!F29+'Balance Sheet'!F31 -> 10946 | H8: ='Balance Sheet'!G29+'Balance Sheet'!G31 -> 10947 | I8: ='Balance Sheet'!H29+'Balance Sheet'!H31 -> 10949 | J8: ='Balance Sheet'!I29+'Balance Sheet'!I31 -> 10950 | ... U8: ='Balance Sheet'!T29+'Balance Sheet'!T31 -> 8466 | V8: =V6+V7 -> 8467 | W8: =W6+W7 -> 7218 | X8: =X6+X7 -> 7219 | Y8: =Y6+Y7 -> 7220 | Z8: =Z6+Z7 -> 7221 | AA8: =AA6+AA7 -> 7222 | AB8: =AB6+AB7 -> 7223 | AC8: =AC6+AC7 -> 7224 | ... AE8: =AE6+AE7 -> 7226
A10: Interest Expenses | D10: ='Income Statement'!C21 -> -53 | E10: ='Income Statement'!D21 -> (60) | F10: ='Income Statement'!E21 -> (62) | G10: ='Income Statement'!F21 -> -61 | H10: ='Income Statement'!G21 -> -68 | I10: ='Income Statement'!H21 -> (65) | J10: ='Income Statement'!I21 -> (65) | K10: ='Income Statement'!J21 -> -64 | ... U10: ='Income Statement'!T21 -> -62 | V10: =V6*V12 -> -55.465806 | W10: =W6*W12 -> -55.472358 | X10: =X6*X12 -> -47.289415 | Y10: =Y6*Y12 -> -47.295967 | Z10: =Z6*Z12 -> -47.302519 | AA10: =AA6*AA12 -> -47.30907 | AB10: =AB6*AB12 -> -47.315622 | AC10: =AC6*AC12 -> -47.322173 | ... AE10: =AE6*AE12 -> -47.335277
A11: Net Interest Expenses | D11: ='Income Statement'!B21+'Income Statement'!$B20 -> -45 | E11: ='Income Statement'!C21+'Income Statement'!$B20 -> -46 | F11: ='Income Statement'!D21+'Income Statement'!$B20 -> -53 | G11: ='Income Statement'!E21+'Income Statement'!$B20 -> -55 | H11: ='Income Statement'!F21+'Income Statement'!$B20 -> -54 | I11: ='Income Statement'!G21+'Income Statement'!$B20 -> -61 | J11: ='Income Statement'!H21+'Income Statement'!$B20 -> -58 | K11: ='Income Statement'!I21+'Income Statement'!$B20 -> -58 | ... U11: ='Income Statement'!S21+'Income Statement'!$B20 -> -56
A12: Interest rate (pre tax) | D12: =D10/D6 -> -0.0076116616 | E12: =E10/E6 -> -0.0086169754 | F12: =F10/F6 -> -0.0051913255 | G12: =G10/G6 -> -0.0055738304 | H12: =H10/H6 -> -0.006212315 | I12: =I10/I6 -> -0.0059376998 | J12: =J10/J6 -> -0.0059366152 | K12: =K10/K6 -> -0.0058447489 | ... U12: =U10/U6 -> -0.0073251418 | V12: =AVERAGE($D12:$U12) -> -0.0065515954 | W12: =AVERAGE($D12:$U12) -> -0.0065515954 | X12: =AVERAGE($D12:$U12) -> -0.0065515954 | Y12: =AVERAGE($D12:$U12) -> -0.0065515954 | Z12: =AVERAGE($D12:$U12) -> -0.0065515954 | AA12: =AVERAGE($D12:$U12) -> -0.0065515954 | AB12: =AVERAGE($D12:$U12) -> -0.0065515954 | AC12: =AVERAGE($D12:$U12) -> -0.0065515954 | ... AE12: =AVERAGE($D12:$U12) -> -0.0065515954

Sheet Fixed Assets
A2: Long-Term Asset Schedule
D4: Historical | V4: Projected
A5: $ in millions | D5: Q1 2022 | E5: =IF(MID(D5,2,1)="4","Q1 "&RIGHT(D5,4)+1, "Q"&MID(D5,2,1)+1&" "&RIGHT(D5,4)) -> Q2 2022 | F5: =IF(MID(E5,2,1)="4","Q1 "&RIGHT(E5,4)+1, "Q"&MID(E5,2,1)+1&" "&RIGHT(E5,4)) -> Q3 2022 | G5: =IF(MID(F5,2,1)="4","Q1 "&RIGHT(F5,4)+1, "Q"&MID(F5,2,1)+1&" "&RIGHT(F5,4)) -> Q4 2022 | H5: =IF(MID(G5,2,1)="4","Q1 "&RIGHT(G5,4)+1, "Q"&MID(G5,2,1)+1&" "&RIGHT(G5,4)) -> Q1 2023 | I5: =IF(MID(H5,2,1)="4","Q1 "&RIGHT(H5,4)+1, "Q"&MID(H5,2,1)+1&" "&RIGHT(H5,4)) -> Q2 2023 | J5: =IF(MID(I5,2,1)="4","Q1 "&RIGHT(I5,4)+1, "Q"&MID(I5,2,1)+1&" "&RIGHT(I5,4)) -> Q3 2023 | K5: =IF(MID(J5,2,1)="4","Q1 "&RIGHT(J5,4)+1, "Q"&MID(J5,2,1)+1&" "&RIGHT(J5,4)) -> Q4 2023 | L5: =IF(MID(K5,2,1)="4","Q1 "&RIGHT(K5,4)+1, "Q"&MID(K5,2,1)+1&" "&RIGHT(K5,4)) -> Q1 2024 | ... AE5: =IF(MID(AD5,2,1)="4","Q1 "&RIGHT(AD5,4)+1, "Q"&MID(AD5,2,1)+1&" "&RIGHT(AD5,4)) -> Q4 2028
A7: Property and Equipment Schedule
A8: Opening balance | D8: ='Balance Sheet'!B17 -> 2149 | E8: ='Balance Sheet'!C17 -> 2268 | F8: ='Balance Sheet'!D17 -> 2364 | G8: ='Balance Sheet'!E17 -> 2509 | H8: ='Balance Sheet'!F17 -> 2778 | I8: ='Balance Sheet'!G17 -> 2916 | J8: ='Balance Sheet'!H17 -> 3233 | K8: ='Balance Sheet'!I17 -> 3774 | ... U8: ='Balance Sheet'!S17 -> 7136 | V8: =U12 -> 9141 | W8: =V12 -> 7419.0108 | X8: =W12 -> 7518.1708 | Y8: =X12 -> 8796.4584 | Z8: =Y12 -> 10291.834 | AA8: =Z12 -> 12197.927 | AB8: =AA12 -> 14364.587 | AC8: =AB12 -> 17656.886 | ... AE8: =AD12 -> 26871.255
A9: Add: Net Purchases | D9: =D10-D8 -> 263 | E9: =E10-E8 -> 244 | F9: =F10-F8 -> 300 | G9: =G10-G8 -> 433 | H9: =H10-H8 -> 317 | I9: =I10-I8 -> 513 | J9: =J10-J8 -> 766 | K9: =K10-K8 -> 278 | ... AE9: =AE10-AE8 -> 4811.0557
A10: Total Fixed Assets | D10: =D12+D11 -> 2412 | E10: =E12+E11 -> 2512 | F10: =F12+F11 -> 2664 | G10: =G12+G11 -> 2942 | H10: =H12+H11 -> 3095 | I10: =I12+I11 -> 3429 | J10: =J12+J11 -> 3999 | K10: =K12+K11 -> 4052 | ... U10: =U12+U11 -> 9667 | V10: ='DCF Valuation'!X10/V16 -> 7111.8292 | W10: ='DCF Valuation'!Y10/W16 -> 7206.8835 | X10: ='DCF Valuation'!Z10/X16 -> 8432.2441 | Y10: ='DCF Valuation'!AA10/Y16 -> 9865.7046 | Z10: ='DCF Valuation'!AB10/Z16 -> 11692.876 | AA10: ='DCF Valuation'!AC10/AA16 -> 13769.827 | AB10: ='DCF Valuation'!AD10/AB16 -> 16925.809 | AC10: ='DCF Valuation'!AE10/AC16 -> 20880.007 | ... AE10: ='DCF Valuation'!AG10/AE16 -> 31682.311
A11: Less: Depreciation | D11: ='DCF Valuation'!F24 -> 144 | E11: ='DCF Valuation'!G24 -> 148 | F11: ='DCF Valuation'!H24 -> 155 | G11: ='DCF Valuation'!I24 -> 164 | H11: ='DCF Valuation'!J24 -> 179 | I11: ='DCF Valuation'!K24 -> 196 | J11: ='DCF Valuation'!L24 -> 225 | K11: ='DCF Valuation'!M24 -> 245 | ... U11: ='DCF Valuation'!W24 -> 526 | V11: =V10*V14 -> -307.18158 | W11: =W10*W14 -> -311.28727 | X11: =X10*X14 -> -364.21432 | Y11: =Y10*Y14 -> -426.12985 | Z11: =Z10*Z14 -> -505.05094 | AA11: =AA10*AA14 -> -594.76079 | AB11: =AB10*AB14 -> -731.07727 | AC11: =AC10*AC14 -> -901.87114 | ... AE11: =AE10*AE14 -> -1368.4556
A12: Closing Balance | C12: ='Balance Sheet'!B17 -> 2149 | D12: ='Balance Sheet'!C17 -> 2268 | E12: ='Balance Sheet'!D17 -> 2364 | F12: ='Balance Sheet'!E17 -> 2509 | G12: ='Balance Sheet'!F17 -> 2778 | H12: ='Balance Sheet'!G17 -> 2916 | I12: ='Balance Sheet'!H17 -> 3233 | J12: ='Balance Sheet'!I17 -> 3774 | ... U12: ='Balance Sheet'!T17 -> 9141 | V12: =V10-V11 -> 7419.0108 | W12: =W10-W11 -> 7518.1708 | X12: =X10-X11 -> 8796.4584 | Y12: =Y10-Y11 -> 10291.834 | Z12: =Z10-Z11 -> 12197.927 | AA12: =AA10-AA11 -> 14364.587 | AB12: =AB10-AB11 -> 17656.886 | AC12: =AC10-AC11 -> 21781.878 | ... AE12: =AE10-AE11 -> 33050.766
A14: Rate of depreciation | D14: =D11/D10 -> 0.059701493 | E14: =E11/E10 -> 0.058917197 | F14: =F11/F10 -> 0.058183183 | G14: =G11/G10 -> 0.055744392 | H14: =H11/H10 -> 0.057835218 | I14: =I11/I10 -> 0.057159522 | J14: =J11/J10 -> 0.056264066 | K14: =K11/K10 -> 0.060463968 | ... U14: =U11/U10 -> 0.054411917 | V14: =AVERAGE($S14:$U14) -> -0.043193048 | W14: =AVERAGE($S14:$U14) -> -0.043193048 | X14: =AVERAGE($S14:$U14) -> -0.043193048 | Y14: =AVERAGE($S14:$U14) -> -0.043193048 | Z14: =AVERAGE($S14:$U14) -> -0.043193048 | AA14: =AVERAGE($S14:$U14) -> -0.043193048 | AB14: =AVERAGE($S14:$U14) -> -0.043193048 | AC14: =AVERAGE($S14:$U14) -> -0.043193048 | ... AE14: =AVERAGE($S14:$U14) -> -0.043193048
A16: Fixed asset turnover ratio | D16: ='DCF Valuation'!F10/D10 -> 2.3470149 | E16: ='DCF Valuation'!G10/E10 -> 2.5903662 | F16: ='DCF Valuation'!H10/F10 -> 2.6662913 | G16: ='DCF Valuation'!I10/G10 -> 2.5978926 | H16: ='DCF Valuation'!J10/H10 -> 2.6778675 | I16: ='DCF Valuation'!K10/I10 -> 1.9550889 | J16: ='DCF Valuation'!L10/J10 -> 1.4831208 | K16: ='DCF Valuation'!M10/K10 -> 1.4933366 | ... U16: ='DCF Valuation'!W10/U10 -> 4.835316 | V16: =AVERAGE($P16:$U16) -> 6.6698733 | W16: =AVERAGE($P16:$U16) -> 6.6698733 | X16: =AVERAGE($P16:$U16) -> 6.6698733 | Y16: =AVERAGE($P16:$U16) -> 6.6698733 | Z16: =AVERAGE($P16:$U16) -> 6.6698733 | AA16: =AVERAGE($P16:$U16) -> 6.6698733 | AB16: =AVERAGE($P16:$U16) -> 6.6698733 | AC16: =AVERAGE($P16:$U16) -> 6.6698733 | ... AE16: =AVERAGE($P16:$U16) -> 6.6698733
A18: Other intangible asset schedule
A19: Opening balance | D19: ='Balance Sheet'!B20 -> 2737 | E19: ='Balance Sheet'!C20 -> 2613 | F19: ='Balance Sheet'!D20 -> 2478 | G19: ='Balance Sheet'!E20 -> 2454 | H19: ='Balance Sheet'!F20 -> 2339 | I19: ='Balance Sheet'!G20 -> 2211 | J19: ='Balance Sheet'!H20 -> 2036 | K19: ='Balance Sheet'!I20 -> 1850 | ... U19: ='Balance Sheet'!S20 -> 769 | V19: =U23 -> 755 | W19: =V23 -> 683.82846 | X19: =W23 -> 628.09185 | Y19: =X23 -> 584.88464 | Z19: =Y23 -> 549.81874 | AA19: =Z23 -> 524.96493 | AB19: =AA23 -> 509.11582 | AC19: =AB23 -> 501.00486 | ... AE19: =AD23 -> 488.10193
A20: Add: Net Purchases | D20: =D21-D19 -> 13 | E20: =E21-E19 -> 3 | F20: =F21-F19 -> 119 | G20: =G21-G19 -> 30 | H20: =H21-H19 -> 27 | I20: =I21-I19 -> 7 | J20: =J21-J19 -> -5 | K20: =K21-K19 -> 7 | ... U20: =U21-U19 -> 129 | V20: =AVERAGE(J20:U20) -> 55.916667 | W20: =AVERAGE(K20:V20) -> 60.993056 | X20: =AVERAGE(L20:W20) -> 65.492477 | Y20: =AVERAGE(M20:X20) -> 67.11685 | Z20: =AVERAGE(N20:Y20) -> 72.709921 | AA20: =AVERAGE(O20:Z20) -> 78.769081 | AB20: =AVERAGE(P20:AA20) -> 84.999838 | AC20: =AVERAGE(Q20:AB20) -> 87.499824 | ... AE20: =AVERAGE(S20:AD20) -> 83.836599
A21: Total Fixed assets | D21: =D23+D22 -> 2750 | E21: =E23+E22 -> 2616 | F21: =F23+F22 -> 2597 | G21: =G23+G22 -> 2484 | H21: =H23+H22 -> 2366 | I21: =I23+I22 -> 2218 | J21: =J23+J22 -> 2031 | K21: =K23+K22 -> 1857 | ... U21: =U23+U22 -> 898 | V21: =V19+V20 -> 810.91667 | W21: =W19+W20 -> 744.82152 | X21: =X19+X20 -> 693.58433 | Y21: =Y19+Y20 -> 652.00149 | Z21: =Z19+Z20 -> 622.52866 | AA21: =AA19+AA20 -> 603.73401 | AB21: =AB19+AB20 -> 594.11566 | AC21: =AC19+AC20 -> 588.50469 | ... AE21: =AE19+AE20 -> 571.93853
A22: Less: Amortization | D22: ='Cash Flow Statement'!B54 -> 137 | E22: ='Cash Flow Statement'!C54 -> 138 | F22: ='Cash Flow Statement'!D54 -> 143 | G22: ='Cash Flow Statement'!E54 -> 145 | H22: ='Cash Flow Statement'!F54 -> 155 | I22: ='Cash Flow Statement'!G54 -> 182 | J22: ='Cash Flow Statement'!H54 -> 181 | K22: ='Cash Flow Statement'!I54 -> 181 | ... U22: ='Cash Flow Statement'!S54 -> 143 | V22: =V21*V25 -> 127.08821 | W22: =W21*W25 -> 116.72966 | X22: =X21*X25 -> 108.69969 | Y22: =Y21*Y25 -> 102.18276 | Z22: =Z21*Z25 -> 97.563724 | AA22: =AA21*AA25 -> 94.618196 | AB22: =AB21*AB25 -> 93.110791 | AC22: =AC21*AC25 -> 92.231431 | ... AE22: =AE21*AE25 -> 89.635155
